INFO:     172.31.196.136:35860 - "POST /users/token HTTP/1.1" 500 Internal Server Error
ERROR:    Exception in ASGI application
Traceback (most recent call last):
  File "asyncpg/protocol/prepared_stmt.pyx", line 175, in asyncpg.protocol.protocol.PreparedStatementState._encode_bind_msg
  File "asyncpg/protocol/codecs/base.pyx", line 227, in asyncpg.protocol.protocol.Codec.encode
  File "asyncpg/protocol/codecs/base.pyx", line 129, in asyncpg.protocol.protocol.Codec.encode_scalar
  File "asyncpg/pgproto/./codecs/int.pyx", line 54, in asyncpg.pgproto.pgproto.int4_encode
TypeError: 'str' object cannot be interpreted as an integer

The above exception was the direct cause of the following exception:

Traceback (most recent call last):
  File "/home/runner/AsyncFastAPIChain/.pythonlibs/lib/python3.11/site-packages/sqlalchemy/dialects/postgresql/asyncpg.py", line 534, in _prepare_and_execute
    self._rows = deque(await prepared_stmt.fetch(*parameters))
                       ^^^^^^^^^^^^^^^^^^^^^^^^^^^^^^^^^^^^^^
  File "/home/runner/AsyncFastAPIChain/.pythonlibs/lib/python3.11/site-packages/asyncpg/prepared_stmt.py", line 176, in fetch
    data = await self.__bind_execute(args, 0, timeout)
           ^^^^^^^^^^^^^^^^^^^^^^^^^^^^^^^^^^^^^^^^^^^
  File "/home/runner/AsyncFastAPIChain/.pythonlibs/lib/python3.11/site-packages/asyncpg/prepared_stmt.py", line 267, in __bind_execute
    data, status, _ = await self.__do_execute(
                      ^^^^^^^^^^^^^^^^^^^^^^^^
  File "/home/runner/AsyncFastAPIChain/.pythonlibs/lib/python3.11/site-packages/asyncpg/prepared_stmt.py", line 256, in __do_execute
    return await executor(protocol)
           ^^^^^^^^^^^^^^^^^^^^^^^^
  File "asyncpg/protocol/protocol.pyx", line 185, in bind_execute
  File "asyncpg/protocol/prepared_stmt.pyx", line 204, in asyncpg.protocol.protocol.PreparedStatementState._encode_bind_msg
asyncpg.exceptions.DataError: invalid input for query argument $1: 'ledger' ('str' object cannot be interpreted as an integer)

The above exception was the direct cause of the following exception:

Traceback (most recent call last):
  File "/home/runner/AsyncFastAPIChain/.pythonlibs/lib/python3.11/site-packages/sqlalchemy/engine/base.py", line 1967, in _exec_single_context
    self.dialect.do_execute(
  File "/home/runner/AsyncFastAPIChain/.pythonlibs/lib/python3.11/site-packages/sqlalchemy/engine/default.py", line 941, in do_execute
    cursor.execute(statement, parameters)
  File "/home/runner/AsyncFastAPIChain/.pythonlibs/lib/python3.11/site-packages/sqlalchemy/dialects/postgresql/asyncpg.py", line 568, in execute
    self._adapt_connection.await_(
  File "/home/runner/AsyncFastAPIChain/.pythonlibs/lib/python3.11/site-packages/sqlalchemy/util/_concurrency_py3k.py", line 132, in await_only
    return current.parent.switch(awaitable)  # type: ignore[no-any-return,attr-defined] # noqa: E501
           ^^^^^^^^^^^^^^^^^^^^^^^^^^^^^^^^
  File "/home/runner/AsyncFastAPIChain/.pythonlibs/lib/python3.11/site-packages/sqlalchemy/util/_concurrency_py3k.py", line 196, in greenlet_spawn
    value = await result
            ^^^^^^^^^^^^
  File "/home/runner/AsyncFastAPIChain/.pythonlibs/lib/python3.11/site-packages/sqlalchemy/dialects/postgresql/asyncpg.py", line 546, in _prepare_and_execute
    self._handle_exception(error)
  File "/home/runner/AsyncFastAPIChain/.pythonlibs/lib/python3.11/site-packages/sqlalchemy/dialects/postgresql/asyncpg.py", line 497, in _handle_exception
    self._adapt_connection._handle_exception(error)
  File "/home/runner/AsyncFastAPIChain/.pythonlibs/lib/python3.11/site-packages/sqlalchemy/dialects/postgresql/asyncpg.py", line 780, in _handle_exception
    raise translated_error from error
sqlalchemy.dialects.postgresql.asyncpg.AsyncAdapt_asyncpg_dbapi.Error: <class 'asyncpg.exceptions.DataError'>: invalid input for query argument $1: 'ledger' ('str' object cannot be interpreted as an integer)

The above exception was the direct cause of the following exception:

Traceback (most recent call last):
  File "/home/runner/AsyncFastAPIChain/.pythonlibs/lib/python3.11/site-packages/uvicorn/protocols/http/h11_impl.py", line 408, in run_asgi
    result = await app(  # type: ignore[func-returns-value]
             ^^^^^^^^^^^^^^^^^^^^^^^^^^^^^^^^^^^^^^^^^^^^^^
  File "/home/runner/AsyncFastAPIChain/.pythonlibs/lib/python3.11/site-packages/uvicorn/middleware/proxy_headers.py", line 84, in __call__
    return await self.app(scope, receive, send)
           ^^^^^^^^^^^^^^^^^^^^^^^^^^^^^^^^^^^^
  File "/home/runner/AsyncFastAPIChain/.pythonlibs/lib/python3.11/site-packages/fastapi/applications.py", line 1054, in __call__
    await super().__call__(scope, receive, send)
  File "/home/runner/AsyncFastAPIChain/.pythonlibs/lib/python3.11/site-packages/starlette/applications.py", line 123, in __call__
    await self.middleware_stack(scope, receive, send)
  File "/home/runner/AsyncFastAPIChain/.pythonlibs/lib/python3.11/site-packages/starlette/middleware/errors.py", line 186, in __call__
    raise exc
  File "/home/runner/AsyncFastAPIChain/.pythonlibs/lib/python3.11/site-packages/starlette/middleware/errors.py", line 164, in __call__
    await self.app(scope, receive, _send)
  File "/home/runner/AsyncFastAPIChain/.pythonlibs/lib/python3.11/site-packages/starlette/middleware/cors.py", line 93, in __call__
    await self.simple_response(scope, receive, send, request_headers=headers)
  File "/home/runner/AsyncFastAPIChain/.pythonlibs/lib/python3.11/site-packages/starlette/middleware/cors.py", line 148, in simple_response
    await self.app(scope, receive, send)
  File "/home/runner/AsyncFastAPIChain/.pythonlibs/lib/python3.11/site-packages/starlette/middleware/exceptions.py", line 65, in __call__
    await wrap_app_handling_exceptions(self.app, conn)(scope, receive, send)
  File "/home/runner/AsyncFastAPIChain/.pythonlibs/lib/python3.11/site-packages/starlette/_exception_handler.py", line 64, in wrapped_app
    raise exc
  File "/home/runner/AsyncFastAPIChain/.pythonlibs/lib/python3.11/site-packages/starlette/_exception_handler.py", line 53, in wrapped_app
    await app(scope, receive, sender)
  File "/home/runner/AsyncFastAPIChain/.pythonlibs/lib/python3.11/site-packages/starlette/routing.py", line 756, in __call__
    await self.middleware_stack(scope, receive, send)
  File "/home/runner/AsyncFastAPIChain/.pythonlibs/lib/python3.11/site-packages/starlette/routing.py", line 776, in app
    await route.handle(scope, receive, send)
  File "/home/runner/AsyncFastAPIChain/.pythonlibs/lib/python3.11/site-packages/starlette/routing.py", line 297, in handle
    await self.app(scope, receive, send)
  File "/home/runner/AsyncFastAPIChain/.pythonlibs/lib/python3.11/site-packages/starlette/routing.py", line 77, in app
    await wrap_app_handling_exceptions(app, request)(scope, receive, send)
  File "/home/runner/AsyncFastAPIChain/.pythonlibs/lib/python3.11/site-packages/starlette/_exception_handler.py", line 64, in wrapped_app
    raise exc
  File "/home/runner/AsyncFastAPIChain/.pythonlibs/lib/python3.11/site-packages/starlette/_exception_handler.py", line 53, in wrapped_app
    await app(scope, receive, sender)
  File "/home/runner/AsyncFastAPIChain/.pythonlibs/lib/python3.11/site-packages/starlette/routing.py", line 72, in app
    response = await func(request)
               ^^^^^^^^^^^^^^^^^^^
  File "/home/runner/AsyncFastAPIChain/.pythonlibs/lib/python3.11/site-packages/fastapi/routing.py", line 301, in app
    raw_response = await run_endpoint_function(
                   ^^^^^^^^^^^^^^^^^^^^^^^^^^^^
  File "/home/runner/AsyncFastAPIChain/.pythonlibs/lib/python3.11/site-packages/fastapi/routing.py", line 212, in run_endpoint_function
    return await dependant.call(**values)
           ^^^^^^^^^^^^^^^^^^^^^^^^^^^^^^
  File "/home/runner/AsyncFastAPIChain/routers/users.py", line 24, in login_for_access_token
    user = await authenticate_user(form_data.username, form_data.password, db)
           ^^^^^^^^^^^^^^^^^^^^^^^^^^^^^^^^^^^^^^^^^^^^^^^^^^^^^^^^^^^^^^^^^^^
  File "/home/runner/AsyncFastAPIChain/auth.py", line 23, in authenticate_user
    user = await db.get(User, username)
           ^^^^^^^^^^^^^^^^^^^^^^^^^^^^
  File "/home/runner/AsyncFastAPIChain/.pythonlibs/lib/python3.11/site-packages/sqlalchemy/ext/asyncio/session.py", line 604, in get
    return await greenlet_spawn(
           ^^^^^^^^^^^^^^^^^^^^^
  File "/home/runner/AsyncFastAPIChain/.pythonlibs/lib/python3.11/site-packages/sqlalchemy/util/_concurrency_py3k.py", line 201, in greenlet_spawn
    result = context.throw(*sys.exc_info())
             ^^^^^^^^^^^^^^^^^^^^^^^^^^^^^^
  File "/home/runner/AsyncFastAPIChain/.pythonlibs/lib/python3.11/site-packages/sqlalchemy/orm/session.py", line 3693, in get
    return self._get_impl(
           ^^^^^^^^^^^^^^^
  File "/home/runner/AsyncFastAPIChain/.pythonlibs/lib/python3.11/site-packages/sqlalchemy/orm/session.py", line 3873, in _get_impl
    return db_load_fn(
           ^^^^^^^^^^^
  File "/home/runner/AsyncFastAPIChain/.pythonlibs/lib/python3.11/site-packages/sqlalchemy/orm/loading.py", line 694, in load_on_pk_identity
    session.execute(
  File "/home/runner/AsyncFastAPIChain/.pythonlibs/lib/python3.11/site-packages/sqlalchemy/orm/session.py", line 2362, in execute
    return self._execute_internal(
           ^^^^^^^^^^^^^^^^^^^^^^^
  File "/home/runner/AsyncFastAPIChain/.pythonlibs/lib/python3.11/site-packages/sqlalchemy/orm/session.py", line 2247, in _execute_internal
    result: Result[Any] = compile_state_cls.orm_execute_statement(
                          ^^^^^^^^^^^^^^^^^^^^^^^^^^^^^^^^^^^^^^^^
  File "/home/runner/AsyncFastAPIChain/.pythonlibs/lib/python3.11/site-packages/sqlalchemy/orm/context.py", line 305, in orm_execute_statement
    result = conn.execute(
             ^^^^^^^^^^^^^
  File "/home/runner/AsyncFastAPIChain/.pythonlibs/lib/python3.11/site-packages/sqlalchemy/engine/base.py", line 1418, in execute
    return meth(
           ^^^^^
  File "/home/runner/AsyncFastAPIChain/.pythonlibs/lib/python3.11/site-packages/sqlalchemy/sql/elements.py", line 515, in _execute_on_connection
    return connection._execute_clauseelement(
           ^^^^^^^^^^^^^^^^^^^^^^^^^^^^^^^^^^
  File "/home/runner/AsyncFastAPIChain/.pythonlibs/lib/python3.11/site-packages/sqlalchemy/engine/base.py", line 1640, in _execute_clauseelement
    ret = self._execute_context(
          ^^^^^^^^^^^^^^^^^^^^^^
  File "/home/runner/AsyncFastAPIChain/.pythonlibs/lib/python3.11/site-packages/sqlalchemy/engine/base.py", line 1846, in _execute_context
    return self._exec_single_context(
           ^^^^^^^^^^^^^^^^^^^^^^^^^^
  File "/home/runner/AsyncFastAPIChain/.pythonlibs/lib/python3.11/site-packages/sqlalchemy/engine/base.py", line 1986, in _exec_single_context
    self._handle_dbapi_exception(
  File "/home/runner/AsyncFastAPIChain/.pythonlibs/lib/python3.11/site-packages/sqlalchemy/engine/base.py", line 2355, in _handle_dbapi_exception
    raise sqlalchemy_exception.with_traceback(exc_info[2]) from e
  File "/home/runner/AsyncFastAPIChain/.pythonlibs/lib/python3.11/site-packages/sqlalchemy/engine/base.py", line 1967, in _exec_single_context
    self.dialect.do_execute(
  File "/home/runner/AsyncFastAPIChain/.pythonlibs/lib/python3.11/site-packages/sqlalchemy/engine/default.py", line 941, in do_execute
    cursor.execute(statement, parameters)
  File "/home/runner/AsyncFastAPIChain/.pythonlibs/lib/python3.11/site-packages/sqlalchemy/dialects/postgresql/asyncpg.py", line 568, in execute
    self._adapt_connection.await_(
  File "/home/runner/AsyncFastAPIChain/.pythonlibs/lib/python3.11/site-packages/sqlalchemy/util/_concurrency_py3k.py", line 132, in await_only
    return current.parent.switch(awaitable)  # type: ignore[no-any-return,attr-defined] # noqa: E501
           ^^^^^^^^^^^^^^^^^^^^^^^^^^^^^^^^
  File "/home/runner/AsyncFastAPIChain/.pythonlibs/lib/python3.11/site-packages/sqlalchemy/util/_concurrency_py3k.py", line 196, in greenlet_spawn
    value = await result
            ^^^^^^^^^^^^
  File "/home/runner/AsyncFastAPIChain/.pythonlibs/lib/python3.11/site-packages/sqlalchemy/dialects/postgresql/asyncpg.py", line 546, in _prepare_and_execute
    self._handle_exception(error)
  File "/home/runner/AsyncFastAPIChain/.pythonlibs/lib/python3.11/site-packages/sqlalchemy/dialects/postgresql/asyncpg.py", line 497, in _handle_exception
    self._adapt_connection._handle_exception(error)
  File "/home/runner/AsyncFastAPIChain/.pythonlibs/lib/python3.11/site-packages/sqlalchemy/dialects/postgresql/asyncpg.py", line 780, in _handle_exception
    raise translated_error from error
sqlalchemy.exc.DBAPIError: (sqlalchemy.dialects.postgresql.asyncpg.Error) <class 'asyncpg.exceptions.DataError'>: invalid input for query argument $1: 'ledger' ('str' object cannot be interpreted as an integer)
[SQL: SELECT "user".id AS user_id, "user".username AS user_username, "user".email AS user_email, "user".hashed_password AS user_hashed_password, "user".is_active AS user_is_active, "user".created_at AS user_created_at 
FROM "user" 
WHERE "user".id = $1::INTEGER]
[parameters: ('ledger',)]
(Background on this error at: https://sqlalche.me/e/20/dbapi)