ERROR:    Exception in ASGI application
Traceback (most recent call last):
  File "/home/runner/AsyncFastAPIChain/.pythonlibs/lib/python3.11/site-packages/sqlalchemy/dialects/postgresql/asyncpg.py", line 826, in _start_transaction
    self._transaction = self._connection.transaction(
                        ^^^^^^^^^^^^^^^^^^^^^^^^^^^^^
  File "/home/runner/AsyncFastAPIChain/.pythonlibs/lib/python3.11/site-packages/asyncpg/connection.py", line 302, in transaction
    self._check_open()
  File "/home/runner/AsyncFastAPIChain/.pythonlibs/lib/python3.11/site-packages/asyncpg/connection.py", line 1596, in _check_open
    raise exceptions.InterfaceError('connection is closed')
asyncpg.exceptions._base.InterfaceError: connection is closed

The above exception was the direct cause of the following exception:

Traceback (most recent call last):
  File "/home/runner/AsyncFastAPIChain/.pythonlibs/lib/python3.11/site-packages/sqlalchemy/engine/base.py", line 1967, in _exec_single_context
    self.dialect.do_execute(
  File "/home/runner/AsyncFastAPIChain/.pythonlibs/lib/python3.11/site-packages/sqlalchemy/engine/default.py", line 941, in do_execute
    cursor.execute(statement, parameters)
  File "/home/runner/AsyncFastAPIChain/.pythonlibs/lib/python3.11/site-packages/sqlalchemy/dialects/postgresql/asyncpg.py", line 568, in execute
    self._adapt_connection.await_(
  File "/home/runner/AsyncFastAPIChain/.pythonlibs/lib/python3.11/site-packages/sqlalchemy/util/_concurrency_py3k.py", line 132, in await_only
    return current.parent.switch(awaitable)  # type: ignore[no-any-return,attr-defined] # noqa: E501
           ^^^^^^^^^^^^^^^^^^^^^^^^^^^^^^^^
  File "/home/runner/AsyncFastAPIChain/.pythonlibs/lib/python3.11/site-packages/sqlalchemy/util/_concurrency_py3k.py", line 196, in greenlet_spawn
    value = await result
            ^^^^^^^^^^^^
  File "/home/runner/AsyncFastAPIChain/.pythonlibs/lib/python3.11/site-packages/sqlalchemy/dialects/postgresql/asyncpg.py", line 504, in _prepare_and_execute
    await adapt_connection._start_transaction()
  File "/home/runner/AsyncFastAPIChain/.pythonlibs/lib/python3.11/site-packages/sqlalchemy/dialects/postgresql/asyncpg.py", line 833, in _start_transaction
    self._handle_exception(error)
  File "/home/runner/AsyncFastAPIChain/.pythonlibs/lib/python3.11/site-packages/sqlalchemy/dialects/postgresql/asyncpg.py", line 780, in _handle_exception
    raise translated_error from error
sqlalchemy.dialects.postgresql.asyncpg.AsyncAdapt_asyncpg_dbapi.InterfaceError: <class 'asyncpg.exceptions._base.InterfaceError'>: connection is closed

The above exception was the direct cause of the following exception:

Traceback (most recent call last):
  File "/home/runner/AsyncFastAPIChain/.pythonlibs/lib/python3.11/site-packages/uvicorn/protocols/http/h11_impl.py", line 408, in run_asgi
    result = await app(  # type: ignore[func-returns-value]
             ^^^^^^^^^^^^^^^^^^^^^^^^^^^^^^^^^^^^^^^^^^^^^^
  File "/home/runner/AsyncFastAPIChain/.pythonlibs/lib/python3.11/site-packages/uvicorn/middleware/proxy_headers.py", line 84, in __call__
    return await self.app(scope, receive, send)
           ^^^^^^^^^^^^^^^^^^^^^^^^^^^^^^^^^^^^
  File "/home/runner/AsyncFastAPIChain/.pythonlibs/lib/python3.11/site-packages/fastapi/applications.py", line 1054, in __call__
    await super().__call__(scope, receive, send)
  File "/home/runner/AsyncFastAPIChain/.pythonlibs/lib/python3.11/site-packages/starlette/applications.py", line 123, in __call__
    await self.middleware_stack(scope, receive, send)
  File "/home/runner/AsyncFastAPIChain/.pythonlibs/lib/python3.11/site-packages/starlette/middleware/errors.py", line 186, in __call__
    raise exc
  File "/home/runner/AsyncFastAPIChain/.pythonlibs/lib/python3.11/site-packages/starlette/middleware/errors.py", line 164, in __call__
    await self.app(scope, receive, _send)
  File "/home/runner/AsyncFastAPIChain/.pythonlibs/lib/python3.11/site-packages/starlette/middleware/base.py", line 189, in __call__
    with collapse_excgroups():
  File "/nix/store/f98g7xbckgqbkagdvpzc2r6lv3h1p9ki-python3-3.11.9/lib/python3.11/contextlib.py", line 158, in __exit__
    self.gen.throw(typ, value, traceback)
  File "/home/runner/AsyncFastAPIChain/.pythonlibs/lib/python3.11/site-packages/starlette/_utils.py", line 93, in collapse_excgroups
    raise exc
  File "/home/runner/AsyncFastAPIChain/.pythonlibs/lib/python3.11/site-packages/starlette/middleware/base.py", line 191, in __call__
    response = await self.dispatch_func(request, call_next)
               ^^^^^^^^^^^^^^^^^^^^^^^^^^^^^^^^^^^^^^^^^^^^
  File "/home/runner/AsyncFastAPIChain/main.py", line 23, in dispatch
    response = await call_next(request)
               ^^^^^^^^^^^^^^^^^^^^^^^^
  File "/home/runner/AsyncFastAPIChain/.pythonlibs/lib/python3.11/site-packages/starlette/middleware/base.py", line 165, in call_next
    raise app_exc
  File "/home/runner/AsyncFastAPIChain/.pythonlibs/lib/python3.11/site-packages/starlette/middleware/base.py", line 151, in coro
    await self.app(scope, receive_or_disconnect, send_no_error)
  File "/home/runner/AsyncFastAPIChain/.pythonlibs/lib/python3.11/site-packages/starlette/middleware/trustedhost.py", line 36, in __call__
    await self.app(scope, receive, send)
  File "/home/runner/AsyncFastAPIChain/.pythonlibs/lib/python3.11/site-packages/starlette/middleware/cors.py", line 85, in __call__
    await self.app(scope, receive, send)
  File "/home/runner/AsyncFastAPIChain/.pythonlibs/lib/python3.11/site-packages/starlette/middleware/exceptions.py", line 65, in __call__
    await wrap_app_handling_exceptions(self.app, conn)(scope, receive, send)
  File "/home/runner/AsyncFastAPIChain/.pythonlibs/lib/python3.11/site-packages/starlette/_exception_handler.py", line 64, in wrapped_app
    raise exc
  File "/home/runner/AsyncFastAPIChain/.pythonlibs/lib/python3.11/site-packages/starlette/_exception_handler.py", line 53, in wrapped_app
    await app(scope, receive, sender)
  File "/home/runner/AsyncFastAPIChain/.pythonlibs/lib/python3.11/site-packages/starlette/routing.py", line 756, in __call__
    await self.middleware_stack(scope, receive, send)
  File "/home/runner/AsyncFastAPIChain/.pythonlibs/lib/python3.11/site-packages/starlette/routing.py", line 776, in app
    await route.handle(scope, receive, send)
  File "/home/runner/AsyncFastAPIChain/.pythonlibs/lib/python3.11/site-packages/starlette/routing.py", line 297, in handle
    await self.app(scope, receive, send)
  File "/home/runner/AsyncFastAPIChain/.pythonlibs/lib/python3.11/site-packages/starlette/routing.py", line 77, in app
    await wrap_app_handling_exceptions(app, request)(scope, receive, send)
  File "/home/runner/AsyncFastAPIChain/.pythonlibs/lib/python3.11/site-packages/starlette/_exception_handler.py", line 64, in wrapped_app
    raise exc
  File "/home/runner/AsyncFastAPIChain/.pythonlibs/lib/python3.11/site-packages/starlette/_exception_handler.py", line 53, in wrapped_app
    await app(scope, receive, sender)
  File "/home/runner/AsyncFastAPIChain/.pythonlibs/lib/python3.11/site-packages/starlette/routing.py", line 72, in app
    response = await func(request)
               ^^^^^^^^^^^^^^^^^^^
  File "/home/runner/AsyncFastAPIChain/.pythonlibs/lib/python3.11/site-packages/fastapi/routing.py", line 301, in app
    raw_response = await run_endpoint_function(
                   ^^^^^^^^^^^^^^^^^^^^^^^^^^^^
  File "/home/runner/AsyncFastAPIChain/.pythonlibs/lib/python3.11/site-packages/fastapi/routing.py", line 212, in run_endpoint_function
    return await dependant.call(**values)
           ^^^^^^^^^^^^^^^^^^^^^^^^^^^^^^
  File "/home/runner/AsyncFastAPIChain/routers/articles.py", line 30, in read_articles
    articles = await get_articles(db, skip=skip, limit=limit)
               ^^^^^^^^^^^^^^^^^^^^^^^^^^^^^^^^^^^^^^^^^^^^^^
  File "/home/runner/AsyncFastAPIChain/crud.py", line 68, in get_articles
    result = await db.execute(select(Article).offset(skip).limit(limit))
             ^^^^^^^^^^^^^^^^^^^^^^^^^^^^^^^^^^^^^^^^^^^^^^^^^^^^^^^^^^^
  File "/home/runner/AsyncFastAPIChain/.pythonlibs/lib/python3.11/site-packages/sqlalchemy/ext/asyncio/session.py", line 461, in execute
    result = await greenlet_spawn(
             ^^^^^^^^^^^^^^^^^^^^^
  File "/home/runner/AsyncFastAPIChain/.pythonlibs/lib/python3.11/site-packages/sqlalchemy/util/_concurrency_py3k.py", line 203, in greenlet_spawn
    result = context.switch(value)
             ^^^^^^^^^^^^^^^^^^^^^
  File "/home/runner/AsyncFastAPIChain/.pythonlibs/lib/python3.11/site-packages/sqlalchemy/orm/session.py", line 2362, in execute
    return self._execute_internal(
           ^^^^^^^^^^^^^^^^^^^^^^^
  File "/home/runner/AsyncFastAPIChain/.pythonlibs/lib/python3.11/site-packages/sqlalchemy/orm/session.py", line 2247, in _execute_internal
    result: Result[Any] = compile_state_cls.orm_execute_statement(
                          ^^^^^^^^^^^^^^^^^^^^^^^^^^^^^^^^^^^^^^^^
  File "/home/runner/AsyncFastAPIChain/.pythonlibs/lib/python3.11/site-packages/sqlalchemy/orm/context.py", line 305, in orm_execute_statement
    result = conn.execute(
             ^^^^^^^^^^^^^
  File "/home/runner/AsyncFastAPIChain/.pythonlibs/lib/python3.11/site-packages/sqlalchemy/engine/base.py", line 1418, in execute
    return meth(
           ^^^^^
  File "/home/runner/AsyncFastAPIChain/.pythonlibs/lib/python3.11/site-packages/sqlalchemy/sql/elements.py", line 515, in _execute_on_connection
    return connection._execute_clauseelement(
           ^^^^^^^^^^^^^^^^^^^^^^^^^^^^^^^^^^
  File "/home/runner/AsyncFastAPIChain/.pythonlibs/lib/python3.11/site-packages/sqlalchemy/engine/base.py", line 1640, in _execute_clauseelement
    ret = self._execute_context(
          ^^^^^^^^^^^^^^^^^^^^^^
  File "/home/runner/AsyncFastAPIChain/.pythonlibs/lib/python3.11/site-packages/sqlalchemy/engine/base.py", line 1846, in _execute_context
    return self._exec_single_context(
           ^^^^^^^^^^^^^^^^^^^^^^^^^^
  File "/home/runner/AsyncFastAPIChain/.pythonlibs/lib/python3.11/site-packages/sqlalchemy/engine/base.py", line 1986, in _exec_single_context
    self._handle_dbapi_exception(
  File "/home/runner/AsyncFastAPIChain/.pythonlibs/lib/python3.11/site-packages/sqlalchemy/engine/base.py", line 2355, in _handle_dbapi_exception
    raise sqlalchemy_exception.with_traceback(exc_info[2]) from e
  File "/home/runner/AsyncFastAPIChain/.pythonlibs/lib/python3.11/site-packages/sqlalchemy/engine/base.py", line 1967, in _exec_single_context
    self.dialect.do_execute(
  File "/home/runner/AsyncFastAPIChain/.pythonlibs/lib/python3.11/site-packages/sqlalchemy/engine/default.py", line 941, in do_execute
    cursor.execute(statement, parameters)
  File "/home/runner/AsyncFastAPIChain/.pythonlibs/lib/python3.11/site-packages/sqlalchemy/dialects/postgresql/asyncpg.py", line 568, in execute
    self._adapt_connection.await_(
  File "/home/runner/AsyncFastAPIChain/.pythonlibs/lib/python3.11/site-packages/sqlalchemy/util/_concurrency_py3k.py", line 132, in await_only
    return current.parent.switch(awaitable)  # type: ignore[no-any-return,attr-defined] # noqa: E501
           ^^^^^^^^^^^^^^^^^^^^^^^^^^^^^^^^
  File "/home/runner/AsyncFastAPIChain/.pythonlibs/lib/python3.11/site-packages/sqlalchemy/util/_concurrency_py3k.py", line 196, in greenlet_spawn
    value = await result
            ^^^^^^^^^^^^
  File "/home/runner/AsyncFastAPIChain/.pythonlibs/lib/python3.11/site-packages/sqlalchemy/dialects/postgresql/asyncpg.py", line 504, in _prepare_and_execute
    await adapt_connection._start_transaction()
  File "/home/runner/AsyncFastAPIChain/.pythonlibs/lib/python3.11/site-packages/sqlalchemy/dialects/postgresql/asyncpg.py", line 833, in _start_transaction
    self._handle_exception(error)
  File "/home/runner/AsyncFastAPIChain/.pythonlibs/lib/python3.11/site-packages/sqlalchemy/dialects/postgresql/asyncpg.py", line 780, in _handle_exception
    raise translated_error from error
sqlalchemy.exc.InterfaceError: (sqlalchemy.dialects.postgresql.asyncpg.InterfaceError) <class 'asyncpg.exceptions._base.InterfaceError'>: connection is closed
[SQL: SELECT article.id, article.title, article.text, article.date, article.user_id, article.is_approved, article.domain, article.links, article.authors, article.publication_date, article.extraction_date 
FROM article 
 LIMIT $1::INTEGER OFFSET $2::INTEGER]
[parameters: (100, 0)]
(Background on this error at: https://sqlalche.me/e/20/rvf5)